Workbook

Sheet SS_Analysis
A1: Boost Conveter Design - Part I
A3: Boost Design Specifications
A5: Parameter | B5: Value | C5: Unit
A6: Max Vin(avg) | B6: 3.5 | C6: V
A7: Min Vin(avg) | B7: 2.5 | C7: V
A8: Nominal Vout(avg) | B8: 5 | C8: V
A9: Max Pout(avg) | B9: 5 | C9: W
A10: Min Pout(avg) | B10: 0.5 | C10: W
A11: Operating fs | B11: 100 | C11: kHz
A14: Evaluating Key Inductor Parameters for CCM (Theoretical)
A16: Parameter | B16: Value | C16: Unit (eq)
A17: Max Operating D | B17: =1-B7/B8 -> 0.5 | C17: (1-1) | D17: ## 1 - minVin/Vout
A18: Min Operating D | B18: =1 - B6/B8 -> 0.3 | C18: (1-2) | D18: ## 1 - maxVin/Vout
A19: Max IL(avg) = Iin(avg) | B19: =B9/B7 -> 2 | C19: A (1-3) | D19: ## maxP/minVin
A20: Min IL(avg) = Iin(avg) | B20: =B10/B6 -> 0.14285714 | C20: A (1-4) | D20: ## minP/maxVin
A21: D for Max L for CCM | B21: 0.33333333 | C21: (1-5) | D21: ## 0.3 < 1/3 <0.5
A22: Max Load R | B22: =B8^2/B10 -> 50 | C22: Ohms | D22: ## Vo^2/Pmin
A23: Min Load R | B23: =B8^2/B9 -> 5 | C23: Ohms | D23: ## Vo^2/Pmax
A24: Min L for CCM | B24: =B22*B21*(1-B21)^2/(2*B11*1000)*1000000 -> 37.037037 | C24: µH (1-6) | D24: ## (Rloadmax*D*(1-D)^2)/2*fs | G24: MinL meaning the min value we can choose - the max value the circuit will reach
A25: Selected L | B25: 50 | C25: µH
A28: Evaluating Output Capacitor (Theoretical)
A30: Parameter | B30: Value | C30: Unit (eq)
A31: Max Vo Ripple | B31: 0.05 | C31: V
A32: Max Iout | B32: =B9/B8 -> 1 | C32: A | D32: ## Pout/Vout
A33: Min Iout | B33: =B10/B8 -> 0.1 | C33: A
A34: Min Co | B34: =(B32*B17)/(B11*1000*B31)*1000000 -> 100 | C34: µF (1-7) | D34: ## （Ioutmax*Dmax)/fs*ripple
A35: Selected Co | B35: 220 | C35: µF
A38: Evaluating Steady-State Operating Conditions (Theoretical)
A40: Parameter | B40: Value | C40: Unit (eq) | D40: Value | E40: Unit (eq) | F40: Value | G40: Unit (eq) | H40: Value | I40: Unit (eq) | J40: Value | K40: Unit (eq) | L40: Value | M40: Unit (eq)
A41: Vout | B41: 5 | C41: V | D41: 5 | E41: V | F41: 5 | G41: V | H41: 5 | I41: V | J41: 5 | K41: V | L41: 5 | M41: V
A42: Vin | B42: 2.5 | C42: V | D42: 3.33 | E42: V | F42: 3.5 | G42: V | H42: 2.5 | I42: V | J42: 3.33 | K42: V | L42: 3.5 | M42: V
A43: Pout | B43: =B10 -> 0.5 | C43: W | D43: =B10 -> 0.5 | E43: W | F43: 0.5 | G43: W | H43: 5 | I43: W | J43: 5 | K43: W | L43: 5 | M43: W
A44: RLoad | B44: =B41^2/B43 -> 50 | C44: Ohms (1-8) | D44: =D41^2/D43 -> 50 | E44: Ohms (1-8) | F44: =F41^2/F43 -> 50 | G44: Ohms (1-8) | H44: =H41^2/H43 -> 5 | I44: Ohms (1-8) | J44: =J41^2/J43 -> 5 | K44: Ohms (1-8) | L44: =L41^2/L43 -> 5 | M44: Ohms (1-8) | N44: ## Vout^2/Pout
A45: Operating D | B45: =1 - B42/B41 -> 0.5 | C45: (1-9) | D45: =1 - D42/D41 -> 0.334 | E45: (1-9) | F45: =1 - F42/F41 -> 0.3 | G45: (1-9) | H45: =1 - H42/H41 -> 0.5 | I45: (1-9) | J45: =1 - J42/J41 -> 0.334 | K45: (1-9) | L45: =1 - L42/L41 -> 0.3 | M45: (1-9) | N45: ##1 - Vin/Vout
A46: Iin(avg) = IL(avg) | B46: =B43/B42 -> 0.2 | C46: A (1-10) | D46: =D43/D42 -> 0.15015015 | E46: A (1-10) | F46: =F43/F42 -> 0.14285714 | G46: A (1-10) | H46: =H43/H42 -> 2 | I46: A (1-10) | J46: =J43/J42 -> 1.5015015 | K46: A (1-10) | L46: =L43/L42 -> 1.4285714 | M46: A (1-10) | N46: ## Pout/Vin
A47: dIL | B47: =B42*B45/(B25*0.000001*B11*1000) -> 0.25 | C47: A (1-11) | D47: =D42*D45/(B25*0.000001*B11*1000) -> 0.222444 | E47: A (1-11) | F47: =F42*F45/(B25*0.000001*B11*1000) -> 0.21 | G47: A (1-11) | H47: =H42*H45/(B25*0.000001*B11*1000) -> 0.25 | I47: A (1-11) | J47: =J42*J45/(B24*0.000001*B11*1000) -> 0.3002994 | K47: A (1-11) | L47: =L42*L45/(B25*0.000001*B11*1000) -> 0.21 | M47: A (1-11) | N47: ## Vin*D)/(L*fs
A48: CCM Achieved | B48: =IF(B46>=B47/2,"Yes","No") -> Yes | D48: =IF(D46>=D47/2,"Yes","No") -> Yes | F48: =IF(F46>=F47/2,"Yes","No") -> Yes | H48: =IF(H46>=H47/2,"Yes","No") -> Yes | J48: =IF(J46>=J47/2,"Yes","No") -> Yes | L48: =IF(L46>=L47/2,"Yes","No") -> Yes
A49: Iin(pk) = IL(pk) | B49: =B46+B47/2 -> 0.325 | C49: A (1-12) | D49: =D46+D47/2 -> 0.26137215 | E49: A (1-12) | F49: =F46+F47/2 -> 0.24785714 | G49: A (1-12) | H49: =H46+H47/2 -> 2.125 | I49: A (1-12) | J49: =J46+J47/2 -> 1.6516512 | K49: A (1-12) | L49: =L46+L47/2 -> 1.5335714 | M49: A (1-12) | N49: avg + delta/2
A50: Iin(rms) = IL(rms) | B50: =SQRT(B46^2 + B47^2/12) -> 0.21262251 | C50: A (1-13) | D50: =SQRT(D46^2 + D47^2/12) -> 0.16330497 | E50: A (1-13) | F50: =SQRT(F46^2 + F47^2/12) -> 0.15518751 | G50: A (1-13) | H50: =SQRT(H46^2 + H47^2/12) -> 2.0013017 | I50: A (1-13) | J50: =SQRT(J46^2 + J47^2/12) -> 1.5040019 | K50: A (1-13) | L50: =SQRT(L46^2 + L47^2/12) -> 1.4298571 | M50: A (1-13) | N50: sqrt(avg^2+delta^2/12)
A51: Iout(avg) = ID(avg) | B51: =B43/B41 -> 0.1 | C51: A (1-14) | D51: =D43/D41 -> 0.1 | E51: A (1-14) | F51: =F43/F41 -> 0.1 | G51: A (1-14) | H51: =H43/H41 -> 1 | I51: A (1-14) | J51: =J43/J41 -> 1 | K51: A (1-14) | L51: =L43/L41 -> 1 | M51: A (1-14) | N51: Pout/Vout
...

Sheet Plots 
A2: Theo VS Sim | B2: Vout
A4: Operating Point | B4: Theo Vout | C4: PLECS Vout (Open loop) | D4: Error %
A5: 2.5V, 0.5W | B5: 5 | C5: 4.486 | D5: =100*(C5-B5)/B5 -> -10.28
A6: 3.33V, 0.5W | B6: 5 | C6: 4.467 | D6: =100*(C6-B6)/B6 -> -10.66
A7: 3.5V, 0.5W | B7: 5 | C7: 4.9853 | D7: =100*(C7-B7)/B7 -> -0.294
A8: 2.5V, 5W | B8: 5 | C8: 4.459 | D8: =100*(C8-B8)/B8 -> -10.82
A9: 3.33V, 5W | B9: 5 | C9: 4.45467 | D9: =100*(C9-B9)/B9 -> -10.9066
A10: 3.5V, 5W | B10: 5 | C10: 4.4869 | D10: =100*(C10-B10)/B10 -> -10.262
A12: Peak Inductor
A13: Operating Point | B13: Theo IL(pk) | C13: PLECS IL(pk) (Open loop) | D13: Error %
A14: 2.5V, 50Ω | B14: 0.325 | C14: 0.303 | D14: =100*(C14-B14)/B14 -> -6.7692308
A15: 3.33V, 50Ω | B15: 0.26137215 | C15: 0.242 | D15: =100*(C15-B15)/B15 -> -7.4117117
A16: 3.5V, 50Ω | B16: 0.24785714 | C16: 0.2334 | D16: =100*(C16-B16)/B16 -> -5.832853
A17: 2.5V, 5Ω | B17: 2.125 | C17: 1.9069 | D17: =100*(C17-B17)/B17 -> -10.263529
A18: 3.33V, 5Ω | B18: 1.6516512 | C18: 1.4386 | D18: =100*(C18-B18)/B18 -> -12.899285
A19: 3.5V, 5Ω | B19: 1.5335714 | C19: 1.386 | D19: =100*(C19-B19)/B19 -> -9.6227294
A21: Operating Point | B21: Theo IL(rms) | C21: PLECS IL(rms) (Open loop) | D21: Error %
A22: 2.5V, 50Ω | B22: 0.21262251 | C22: 0.195 | D22: =100*(C22-B22)/B22 -> -8.2881692
A23: 3.33V, 50Ω | B23: 0.16330497 | C23: 0.1476 | D23: =100*(C23-B23)/B23 -> -9.6169557
A24: 3.5V, 50Ω | B24: 0.15518751 | C24: 0.1421 | D24: =100*(C24-B24)/B24 -> -8.4333527
A25: 2.5V, 5Ω | B25: 2.0013017 | C25: 1.7852 | D25: =100*(C25-B25)/B25 -> -10.798055
A26: 3.33V, 5Ω | B26: 1.5040019 | C26: 1.3312 | D26: =100*(C26-B26)/B26 -> -11.489474
A27: 3.5V, 5Ω | B27: 1.4298571 | C27: 1.28335 | D27: =100*(C27-B27)/B27 -> -10.246276
A29: Operating Point | B29: Theo Vripple | C29: PLECS Vripple (Open loop) | D29: Error %
A30: 2.5V, 50Ω | B30: 0.0022727273 | C30: 0.0026 | D30: =100*(C30-B30)/B30 -> 14.4
A31: 3.33V, 50Ω | B31: 0.0015181818 | C31: 0.00213 | D31: =100*(C31-B31)/B31 -> 40.299401
A32: 3.5V, 50Ω | B32: 0.0013636364 | C32: 0.00208 | D32: =100*(C32-B32)/B32 -> 52.533333
A33: 2.5V, 5Ω | B33: 0.022727273 | C33: 0.0285 | D33: =100*(C33-B33)/B33 -> 25.4
A34: 3.33V, 5Ω | B34: 0.015181818 | C34: 0.0194 | D34: =100*(C34-B34)/B34 -> 27.784431
A35: 3.5V, 5Ω | B35: 0.013636364 | C35: 0.018 | D35: =100*(C35-B35)/B35 -> 32

Sheet BOM
A16: Boost Converter Stage | B16: Type | C16: Purpose
A17: L1 | B17: Custom wound Inductor | C17: Main boost energy storage
A18: Q1 | B18: N-channel MOSFET | C18: switching for 100khz | D18: 13 | E18: MOSFET | F18: IRFZ46NPBF | G18: N-Channel 55 V 53A (Ta) | H18: TO220 | I18: Digikey | J18: IRFZ46NPBF-ND
A19: D1 | B19: Schottky diode | C19: boost rectifier diode | D19: 37 | E19: Schottky diode | F19: SSA34-E3/61T | G19: DIODE SCHOTTKY 40V 3A DO214 | H19: DO214 | I19: Digikey | J19: SSA34-E3/61TGITR-ND
A20: R5 | B20: shunt resistor | C20: Measures mosfet and inductor current for feedback | D20: https://www.digikey.com/en/products/detail/riedon-products-by-bourns/UB5C-0R33F1/2176622
A21: R2 | B21: MOSFET gate resistor | C21: Controls gate switching speed
A22: R3 | B22: MOSFET gate sourse pull down resistor | C22: Keeps MOSFET OFF when gate is undriven
A23: C1 | B23: Bulk polarized input capacitor | C23: reduces low-frequency input ripple
A24: C3,C4 | B24: Decoupling Capacitor | C24: High frequency filtering, provide low impedance path for switching frequency noise
A25: C2 | B25: Output Capacitor | C25: Stores Energy and reduces output voltage ripple | D25: 6 | E25: Bulk electrolytic capacitors - choice 2 | F25: UCL1V221MNL1GS | G25: 220 µF 35 V Alum, 80mOhm @ 100kHz 2000 Hrs @ 105°C | H25: CR08 | I25: Digikey | J25: 493-3957-2-ND
A26: C5,C6 | B26: Decoupling Capacitor | C26: High frequency filtering, provide low impedance path for switching frequency noise
A28: UC3843 PWM Controller
A33: Section | B33: Schematic refs | C33: Generic component type | D33: Purpose
A34: 1. Boost power stage | B34: L1 | C34: Power inductor / custom wound inductor | D34: Main boost energy-storage inductor
B35: Q1 | C35: N-channel power MOSFET | D35: Main 100 kHz switching device
B36: D1 | C36: Power Schottky diode | D36: Boost rectifier diode
B37: R5 | C37: Low-value current-sense / shunt resistor | D37: Measures MOSFET/inductor current
B38: R2 | C38: MOSFET gate resistor | D38: Controls gate switching speed/ringing
B39: R3 | C39: MOSFET gate-source pull-down resistor | D39: Keeps MOSFET OFF when gate is undriven
A40: 2. Input/output power capacitors | B40: C1 | C40: Bulk polarized input capacitor | D40: Low-frequency input energy buffering
B41: C3, C4 | C41: Ceramic input bypass/ripple capacitors | D41: High-frequency switching current filtering
B42: C2 | C42: Bulk polarized output capacitor | D42: Output energy storage / low-frequency ripple
B43: C5, C6 | C43: Ceramic output bypass/ripple capacitors | D43: High-frequency output ripple filtering
A44: 3. UC3843 PWM controller | B44: U1 | C44: UC3843 current-mode PWM controller IC | D44: Generates MOSFET gate PWM
B45: C15, C16 | C45: 10 V supply decoupling/bulk capacitors | D45: UC3843 VCC decoupling
B46: C10 | C46: Ceramic VREF decoupling capacitor | D46: Stabilises UC3843 5 V reference
A47: 4. UC3843 oscillator / switching-frequency setting | B47: R18 | C47: Timing resistor | D47: Sets UC3843 oscillator frequency
B48: C11 | C48: Timing capacitor | D48: Sets UC3843 oscillator frequency
A49: 5. Current-feedback signal conditioning | B49: U2B | C49: Op-amp current-sense amplifier / signal conditioner | D49: Amplifies/conditions voltage from R5
B50: R11, R12, R14 | C50: Signal-conditioning resistors | D50: Input scaling/filtering
B51: R6, R8 | C51: Op-amp gain-setting resistors | D51: Set current feedback amplifier gain
B52: C7, C8 | C52: Small-signal ceramic filter/compensation capacitors | D52: Remove switching noise / control bandwidth
B53: R10 | C53: Slope-compensation injection resistor | D53: Adds slope-compensation ramp to current feedback
A54: 6. Slope-compensation generator | B54: Q2 | C54: Small-signal BJT transistor | D54: Generates/conditions oscillator ramp
B55: D2 | C55: Small-signal switching diode | D55: Directs slope-compensation signal
B56: R23 | C56: Small-signal resistor | D56: Bias/discharge path
B57: C13 | C57: Small-signal ceramic capacitor | D57: AC coupling / ramp shaping
A58: 7. MCU PI → UC3843 control interface | B58: R17, R19, R20, R21 | C58: Small-signal / control-loop resistors | D58: Scale and interface MCU PI command with UC3843
B59: C9 | C59: Compensation capacitor | D59: UC3843 COMP/VFB control-loop compensation
B60: C12 | C60: Ceramic RC-filter capacitor | D60: Filters MCU PI/control signal
...

Sheet Inductor_Design
A1: Inductor Design - Part II
A3: Transformer Design Specifications
A5: Parameter | B5: Value | C5: Unit
A6: Selected L | B6: =SS_Analysis!B25 -> 50 | C6: µH
A7: Max IL(avg) | B7: =SS_Analysis!H46 -> 2 | C7: A
A8: Max IL(pk) | B8: =SS_Analysis!H49 -> 2.125 | C8: A
A9: Max RMS IL | B9: =SS_Analysis!H50 -> 2.0013017 | C9: A
A10: Max Bmax | B10: 0.25 | C10: T
A11: Operating fs | B11: =SS_Analysis!B11 -> 100 | C11: kHz
A14: Core, Former & Magnet Wire Details
A16: Parameter | B16: Value | C16: Unit
A17: Core type | B17: EFD20
A18: Core material | B18: N97
A19: Ae | B19: 31 | C19: mm^2
A20: le | B20: 47 | C20: mm
A21: Ve | B21: 1460 | C21: mm^3
A22: AN | B22: 28.1 | C22: mm^2
A23: ln | B23: 40.2 | C23: mm
A24: Wire ρ | B24: 1.7241e-08 | C24: Ωm
A25: µ0 | B25: =PI()*0.0000004 -> 1.2566371e-06 | C25: H/m
A26: µe | B26: 1510
A27: Achievable Kf | B27: 0.5
A30: Evaluating Inductor Parameters
A32: Parameter | B32: Value | C32: Unit (eq)
A33: Selected lg | B33: 0.1 | C33: mm
A34: Np | B34: =SQRT((B6*0.000001)*(B20*0.001+2*B33*0.001*B26)/(B25*B26*B19*0.000001)) -> 17.223581 | C34: Turns (1-1)
A35: Bmax | B35: =(B6*0.000001*B8)/(B34*B19*0.000001) -> 0.19899574 | C35: T (1-2)
A36: Bmax < Max Bmax | B36: =IF(B35<=B10,"Yes","No") -> Yes
A37: Skin Depth | B37: =SQRT((2*B24)/(2*PI()*B11*1000*B25))*1000 -> 0.20897838 | C37: mm (1-3)
A38: Selected Wire Diameter | B38: =2*B37 -> 0.41795676 | C38: mm
A39: Wire Acu | B39: =(PI()*(B38)^2)/4 -> 0.13719952 | C39: mm^2 (1-4)
A40: Current density without Np | B40: =B9/B39 -> 14.586798 | C40: A/mm^2
A41: Parallel Wires | B41: =ROUNDDOWN((B22*B27)/(B34*B39),0) -> 5
A42: Current density J | B42: =B9/(B39*B41) -> 2.9173596 | C42: A/mm^2
A43: Rdc of Inductor | B43: =(B24*B23*0.001*B34)/(B39*0.000001*B41)*1000 -> 17.401608 | C43: mOhms (1-5)
A44: Max Rdc Loss in Lp | B44: =B9^2*B43 -> 69.697065 | C44: mW (1-6)
A47: Experimental Results
A49: Parameter | B49: Value | C49: Unit (eq)
A50: Inductance | C50: uH
A51: Bmax | C51: T
...
