Workbook

Sheet SS_Analysis
A1: Boost Conveter Design - Part I
A3: Boost Design Specifications
A5: Parameter | B5: Value | C5: Unit
A6: Max Vin(avg) | B6: 3.5 | C6: V
A7: Min Vin(avg) | B7: 2.5 | C7: V
A8: Nominal Vout(avg) | B8: 5 | C8: V
A9: Max Pout(avg) | B9: 5 | C9: W
A10: Min Pout(avg) | B10: 0.5 | C10: W
A11: Operating fs | B11: 100 | C11: kHz
A14: Evaluating Key Inductor Parameters for CCM (Theoretical)
A16: Parameter | B16: Value | C16: Unit (eq)
A17: Max Operating D | B17: =1-B7/B8 -> 0.5 | C17: (1-1) | D17: ## 1 - minVin/Vout
A18: Min Operating D | B18: =1 - B6/B8 -> 0.3 | C18: (1-2) | D18: ## 1 - maxVin/Vout
A19: Max IL(avg) = Iin(avg) | B19: =B9/B7 -> 2 | C19: A (1-3) | D19: ## maxP/minVin
A20: Min IL(avg) = Iin(avg) | B20: =B10/B6 -> 0.14285714 | C20: A (1-4) | D20: ## minP/maxVin
A21: D for Max L for CCM | B21: 0.33333333 | C21: (1-5) | D21: ## 0.3 < 1/3 <0.5
A22: Max Load R | B22: =B8^2/B10 -> 50 | C22: Ohms | D22: ## Vo^2/Pmin
A23: Min Load R | B23: =B8^2/B9 -> 5 | C23: Ohms | D23: ## Vo^2/Pmax
A24: Min L for CCM | B24: =B22*B21*(1-B21)^2/(2*B11*1000)*1000000 -> 37.037037 | C24: µH (1-6) | D24: ## (Rloadmax*D*(1-D)^2)/2*fs | G24: MinL meaning the min value we can choose - the max value the circuit will reach
A25: Selected L | B25: 50 | C25: µH
A28: Evaluating Output Capacitor (Theoretical)
A30: Parameter | B30: Value | C30: Unit (eq)
A31: Max Vo Ripple | B31: 0.05 | C31: V
A32: Max Iout | B32: =B9/B8 -> 1 | C32: A | D32: ## Pout/Vout
A33: Min Iout | B33: =B10/B8 -> 0.1 | C33: A
A34: Min Co | B34: =(B32*B17)/(B11*1000*B31)*1000000 -> 100 | C34: µF (1-7) | D34: ## （Ioutmax*Dmax)/fs*ripple
A35: Selected Co | B35: 220 | C35: µF
A38: Evaluating Steady-State Operating Conditions (Theoretical)
A40: Parameter | B40: Value | C40: Unit (eq) | D40: Value | E40: Unit (eq) | F40: Value | G40: Unit (eq) | H40: Value | I40: Unit (eq) | J40: Value | K40: Unit (eq) | L40: Value | M40: Unit (eq)
A41: Vout | B41: 5 | C41: V | D41: 5 | E41: V | F41: 5 | G41: V | H41: 5 | I41: V | J41: 5 | K41: V | L41: 5 | M41: V
A42: Vin | B42: 2.5 | C42: V | D42: 3.33 | E42: V | F42: 3.5 | G42: V | H42: 2.5 | I42: V | J42: 3.33 | K42: V | L42: 3.5 | M42: V
A43: Pout | B43: =B10 -> 0.5 | C43: W | D43: =B10 -> 0.5 | E43: W | F43: 0.5 | G43: W | H43: 5 | I43: W | J43: 5 | K43: W | L43: 5 | M43: W
A44: RLoad | B44: =B41^2/B43 -> 50 | C44: Ohms (1-8) | D44: =D41^2/D43 -> 50 | E44: Ohms (1-8) | F44: =F41^2/F43 -> 50 | G44: Ohms (1-8) | H44: =H41^2/H43 -> 5 | I44: Ohms (1-8) | J44: =J41^2/J43 -> 5 | K44: Ohms (1-8) | L44: =L41^2/L43 -> 5 | M44: Ohms (1-8) | N44: ## Vout^2/Pout
A45: Operating D | B45: =1 - B42/B41 -> 0.5 | C45: (1-9) | D45: =1 - D42/D41 -> 0.334 | E45: (1-9) | F45: =1 - F42/F41 -> 0.3 | G45: (1-9) | H45: =1 - H42/H41 -> 0.5 | I45: (1-9) | J45: =1 - J42/J41 -> 0.334 | K45: (1-9) | L45: =1 - L42/L41 -> 0.3 | M45: (1-9) | N45: ##1 - Vin/Vout
A46: Iin(avg) = IL(avg) | B46: =B43/B42 -> 0.2 | C46: A (1-10) | D46: =D43/D42 -> 0.15015015 | E46: A (1-10) | F46: =F43/F42 -> 0.14285714 | G46: A (1-10) | H46: =H43/H42 -> 2 | I46: A (1-10) | J46: =J43/J42 -> 1.5015015 | K46: A (1-10) | L46: =L43/L42 -> 1.4285714 | M46: A (1-10) | N46: ## Pout/Vin
A47: dIL | B47: =B42*B45/(B25*0.000001*B11*1000) -> 0.25 | C47: A (1-11) | D47: =D42*D45/(B25*0.000001*B11*1000) -> 0.222444 | E47: A (1-11) | F47: =F42*F45/(B25*0.000001*B11*1000) -> 0.21 | G47: A (1-11) | H47: =H42*H45/(B25*0.000001*B11*1000) -> 0.25 | I47: A (1-11) | J47: =J42*J45/(B24*0.000001*B11*1000) -> 0.3002994 | K47: A (1-11) | L47: =L42*L45/(B25*0.000001*B11*1000) -> 0.21 | M47: A (1-11) | N47: ## Vin*D)/(L*fs
A48: CCM Achieved | B48: =IF(B46>=B47/2,"Yes","No") -> Yes | D48: =IF(D46>=D47/2,"Yes","No") -> Yes | F48: =IF(F46>=F47/2,"Yes","No") -> Yes | H48: =IF(H46>=H47/2,"Yes","No") -> Yes | J48: =IF(J46>=J47/2,"Yes","No") -> Yes | L48: =IF(L46>=L47/2,"Yes","No") -> Yes
A49: Iin(pk) = IL(pk) | B49: =B46+B47/2 -> 0.325 | C49: A (1-12) | D49: =D46+D47/2 -> 0.26137215 | E49: A (1-12) | F49: =F46+F47/2 -> 0.24785714 | G49: A (1-12) | H49: =H46+H47/2 -> 2.125 | I49: A (1-12) | J49: =J46+J47/2 -> 1.6516512 | K49: A (1-12) | L49: =L46+L47/2 -> 1.5335714 | M49: A (1-12) | N49: avg + delta/2
A50: Iin(rms) = IL(rms) | B50: =SQRT(B46^2 + B47^2/12) -> 0.21262251 | C50: A (1-13) | D50: =SQRT(D46^2 + D47^2/12) -> 0.16330497 | E50: A (1-13) | F50: =SQRT(F46^2 + F47^2/12) -> 0.15518751 | G50: A (1-13) | H50: =SQRT(H46^2 + H47^2/12) -> 2.0013017 | I50: A (1-13) | J50: =SQRT(J46^2 + J47^2/12) -> 1.5040019 | K50: A (1-13) | L50: =SQRT(L46^2 + L47^2/12) -> 1.4298571 | M50: A (1-13) | N50: sqrt(avg^2+delta^2/12)
A51: Iout(avg) = ID(avg) | B51: =B43/B41 -> 0.1 | C51: A (1-14) | D51: =D43/D41 -> 0.1 | E51: A (1-14) | F51: =F43/F41 -> 0.1 | G51: A (1-14) | H51: =H43/H41 -> 1 | I51: A (1-14) | J51: =J43/J41 -> 1 | K51: A (1-14) | L51: =L43/L41 -> 1 | M51: A (1-14) | N51: Pout/Vout
...

Sheet Inductor_Design
A1: Inductor Design - Part II
A3: Transformer Design Specifications
A5: Parameter | B5: Value | C5: Unit
A6: Selected L | B6: =SS_Analysis!B25 -> 50 | C6: µH
A7: Max IL(avg) | B7: =SS_Analysis!H46 -> 2 | C7: A
A8: Max IL(pk) | B8: =SS_Analysis!H49 -> 2.125 | C8: A
A9: Max RMS IL | B9: =SS_Analysis!H50 -> 2.0013017 | C9: A
A10: Max Bmax | B10: 0.25 | C10: T
A11: Operating fs | B11: =SS_Analysis!B11 -> 100 | C11: kHz
A14: Core, Former & Magnet Wire Details
A16: Parameter | B16: Value | C16: Unit
A17: Core type | B17: EFD20
A18: Core material | B18: N97
A19: Ae | C19: mm^2
A20: le | C20: mm
A21: Ve | C21: mm^3
A22: AN | C22: mm^2
A23: ln | C23: mm
A24: Wire ρ | C24: Ωm
A25: µ0 | C25: H/m
A26: µe
A27: Achievable Kf | B27: 0.65
A30: Evaluating Inductor Parameters
A32: Parameter | B32: Value | C32: Unit (eq)
A33: Selected lg | B33: 0.1 | C33: mm
A34: Np | C34: Turns (1-1)
A35: Bmax | C35: T (1-2)
A36: Bmax < Max Bmax | B36: =IF(B35<=B10,"Yes","No") -> Yes
A37: Skin Depth | C37: mm (1-3)
A38: Selected Wire Diameter | B38: 0.5 | C38: mm
A39: Wire Acu | C39: mm^2 (1-4)
A40: Parallel Wires | B40: 5
A41: Rdc of Inductor | C41: mOhms (1-5)
A42: Max Rdc Loss in Lp | C42: W (1-6)
A45: Experimental Results
A47: Parameter | B47: Value | C47: Unit (eq)
A48: Inductance | C48: uH
A49: Bmax | C49: T
A50: Rdc | C50: T
A51: Rac | C51: mOhm
